Workbook

Sheet Статистика акций за год
B2: Данные акций за год
A3: Дата | B3: Аэрофлот | C3: Газпром | D3: МТС | E3: Роснефть | F3: Сбербанк | G3: Башнефть | H3: М.видео | I3: ПИК | J3: Татнефть | K3: Индекс РТС | L3: Доходность облигаций на год (бескупонных с сайта ЦБ РФ)
A4: 45268 | B4: 35.66 | C4: 161.5 | D4: 251.75 | E4: 564.7 | F4: 265.16 | G4: 2175.5 | H4: 176.1 | I4: 668.4 | J4: 637.7 | K4: 1054.28 | L4: 0.1233
A5: 45267 | B5: 34.94 | C5: 163.38 | D5: 251.65 | E5: 560.6 | F5: 265.12 | G5: 2180 | H5: 173.5 | I5: 655.5 | J5: 626.2 | K5: 1051.21 | L5: 0.1236
A6: 45266 | B6: 35.24 | C6: 158.74 | D6: 248.2 | E6: 565.55 | F6: 267.58 | G6: 2179 | H6: 173.4 | I6: 658.6 | J6: 622.2 | K6: 1045.28 | L6: 0.1232
A7: 45265 | B7: 36.06 | C7: 160.46 | D7: 253.45 | E7: 574.35 | F7: 279.62 | G7: 2246 | H7: 175.4 | I7: 676 | J7: 635.2 | K7: 1066.13 | L7: 0.1246
A8: 45264 | B8: 35.8 | C8: 160.01 | D8: 248.75 | E8: 565 | F8: 270.96 | G8: 2180 | H8: 166.3 | I8: 666.5 | J8: 623.7 | K8: 1076.99 | L8: 0.1253
A9: 45261 | B9: 36.51 | C9: 162.61 | D9: 250.15 | E9: 575.15 | F9: 273.97 | G9: 2310.5 | H9: 172.7 | I9: 666 | J9: 632.5 | K9: 1095.28 | L9: 0.1242
A10: 45260 | B10: 36.29 | C10: 163.23 | D10: 254.45 | E10: 584.3 | F10: 277.5 | G10: 2434.5 | H10: 174.5 | I10: 676.5 | J10: 638.8 | K10: 1115.01 | L10: 0.115
A11: 45259 | B11: 36.72 | C11: 163.17 | D11: 256.5 | E11: 593.45 | F11: 276.8 | G11: 2458.5 | H11: 176.8 | I11: 695.4 | J11: 638.7 | K11: 1128.01 | L11: 0.1143
A12: 45258 | B12: 37.15 | C12: 164.21 | D12: 261.25 | E12: 589.9 | F12: 279.91 | G12: 2422 | H12: 180 | I12: 709.5 | J12: 641.2 | K12: 1128.61 | L12: 0.116
A13: 45257 | B13: 37.82 | C13: 162.79 | D13: 260.2 | E13: 578 | F13: 282.33 | G13: 2400.5 | H13: 175.8 | I13: 703 | J13: 638.4 | K13: 1132.05 | L13: 0.1155
A14: 45254 | B14: 38.51 | C14: 164.71 | D14: 262.85 | E14: 578.85 | F14: 286.85 | G14: 2340 | H14: 180.8 | I14: 705.8 | J14: 648 | K14: 1143.15 | L14: 0.1154
A15: 45253 | B15: 38.67 | C15: 164.11 | D15: 266.25 | E15: 580.8 | F15: 286.19 | G15: 2321 | H15: 183.8 | I15: 702.9 | J15: 641.1 | K15: 1148.97 | L15: 0.1151
... A257: 44907 | B257: 24.76 | C257: 162.89 | D257: 231.1 | E257: 335.2 | F257: 139.48 | G257: 929 | H257: 166.6 | I257: 593.4 | J257: 360.1 | K257: 1088.86 | L257: 0.0711

Sheet Доходность
B2: Доходность акций
A3: Дата | B3: Аэрофлот | C3: Газпром | D3: МТС | E3: Роснефть | F3: Сбербанк | G3: Башнефть | H3: М.видео | I3: ПИК | J3: Татнефть | K3: Индекс РТС | L3: Доходность облигаций на год (бескупонных с сайта ЦБ РФ) | M3: Доходность на 1 день
A4: 45268 | B4: =('Статистика акций за год'!B4-'Статистика акций за год'!B5)/'Статистика акций за год'!B5 -> 0.020606754 | C4: =('Статистика акций за год'!C4-'Статистика акций за год'!C5)/'Статистика акций за год'!C5 -> -0.011506916 | D4: =('Статистика акций за год'!D4-'Статистика акций за год'!D5)/'Статистика акций за год'!D5 -> 0.00039737731 | E4: =('Статистика акций за год'!E4-'Статистика акций за год'!E5)/'Статистика акций за год'!E5 -> 0.0073135926 | F4: =('Статистика акций за год'!F4-'Статистика акций за год'!F5)/'Статистика акций за год'!F5 -> 0.00015087508 | G4: =('Статистика акций за год'!G4-'Статистика акций за год'!G5)/'Статистика акций за год'!G5 -> -0.0020642202 | H4: =('Статистика акций за год'!H4-'Статистика акций за год'!H5)/'Статистика акций за год'!H5 -> 0.014985591 | I4: =('Статистика акций за год'!I4-'Статистика акций за год'!I5)/'Статистика акций за год'!I5 -> 0.019679634 | ... K4: =('Статистика акций за год'!K4-'Статистика акций за год'!K5)/'Статистика акций за год'!K5 -> 0.0029204441 | L4: 0.1233 | M4: =POWER(L4+1,1/365)-1 -> 0.00031860083
A5: 45267 | B5: =('Статистика акций за год'!B5-'Статистика акций за год'!B6)/'Статистика акций за год'!B6 -> -0.0085130533 | C5: =('Статистика акций за год'!C5-'Статистика акций за год'!C6)/'Статистика акций за год'!C6 -> 0.029230188 | D5: =('Статистика акций за год'!D5-'Статистика акций за год'!D6)/'Статистика акций за год'!D6 -> 0.013900081 | E5: =('Статистика акций за год'!E5-'Статистика акций за год'!E6)/'Статистика акций за год'!E6 -> -0.0087525418 | F5: =('Статистика акций за год'!F5-'Статистика акций за год'!F6)/'Статистика акций за год'!F6 -> -0.0091935122 | G5: =('Статистика акций за год'!G5-'Статистика акций за год'!G6)/'Статистика акций за год'!G6 -> 0.00045892611 | H5: =('Статистика акций за год'!H5-'Статистика акций за год'!H6)/'Статистика акций за год'!H6 -> 0.00057670127 | I5: =('Статистика акций за год'!I5-'Статистика акций за год'!I6)/'Статистика акций за год'!I6 -> -0.0047069541 | ... K5: =('Статистика акций за год'!K5-'Статистика акций за год'!K6)/'Статистика акций за год'!K6 -> 0.0056731211 | L5: 0.1236 | M5: =POWER(L5+1,1/365)-1 -> 0.00031933266
A6: 45266 | B6: =('Статистика акций за год'!B6-'Статистика акций за год'!B7)/'Статистика акций за год'!B7 -> -0.022739878 | C6: =('Статистика акций за год'!C6-'Статистика акций за год'!C7)/'Статистика акций за год'!C7 -> -0.010719182 | D6: =('Статистика акций за год'!D6-'Статистика акций за год'!D7)/'Статистика акций за год'!D7 -> -0.020714145 | E6: =('Статистика акций за год'!E6-'Статистика акций за год'!E7)/'Статистика акций за год'!E7 -> -0.015321668 | F6: =('Статистика акций за год'!F6-'Статистика акций за год'!F7)/'Статистика акций за год'!F7 -> -0.043058436 | G6: =('Статистика акций за год'!G6-'Статистика акций за год'!G7)/'Статистика акций за год'!G7 -> -0.02983081 | H6: =('Статистика акций за год'!H6-'Статистика акций за год'!H7)/'Статистика акций за год'!H7 -> -0.011402509 | I6: =('Статистика акций за год'!I6-'Статистика акций за год'!I7)/'Статистика акций за год'!I7 -> -0.025739645 | ... K6: =('Статистика акций за год'!K6-'Статистика акций за год'!K7)/'Статистика акций за год'!K7 -> -0.019556714 | L6: 0.1232 | M6: =POWER(L6+1,1/365)-1 -> 0.00031835684
A7: 45265 | B7: =('Статистика акций за год'!B7-'Статистика акций за год'!B8)/'Статистика акций за год'!B8 -> 0.0072625698 | C7: =('Статистика акций за год'!C7-'Статистика акций за год'!C8)/'Статистика акций за год'!C8 -> 0.0028123242 | D7: =('Статистика акций за год'!D7-'Статистика акций за год'!D8)/'Статистика акций за год'!D8 -> 0.018894472 | E7: =('Статистика акций за год'!E7-'Статистика акций за год'!E8)/'Статистика акций за год'!E8 -> 0.016548673 | F7: =('Статистика акций за год'!F7-'Статистика акций за год'!F8)/'Статистика акций за год'!F8 -> 0.031960437 | G7: =('Статистика акций за год'!G7-'Статистика акций за год'!G8)/'Статистика акций за год'!G8 -> 0.030275229 | H7: =('Статистика акций за год'!H7-'Статистика акций за год'!H8)/'Статистика акций за год'!H8 -> 0.054720385 | I7: =('Статистика акций за год'!I7-'Статистика акций за год'!I8)/'Статистика акций за год'!I8 -> 0.014253563 | ... K7: =('Статистика акций за год'!K7-'Статистика акций за год'!K8)/'Статистика акций за год'!K8 -> -0.010083659 | L7: 0.1246 | M7: =POWER(L7+1,1/365)-1 -> 0.00032177071
A8: 45264 | B8: =('Статистика акций за год'!B8-'Статистика акций за год'!B9)/'Статистика акций за год'!B9 -> -0.019446727 | C8: =('Статистика акций за год'!C8-'Статистика акций за год'!C9)/'Статистика акций за год'!C9 -> -0.015989177 | D8: =('Статистика акций за год'!D8-'Статистика акций за год'!D9)/'Статистика акций за год'!D9 -> -0.005596642 | E8: =('Статистика акций за год'!E8-'Статистика акций за год'!E9)/'Статистика акций за год'!E9 -> -0.01764757 | F8: =('Статистика акций за год'!F8-'Статистика акций за год'!F9)/'Статистика акций за год'!F9 -> -0.010986604 | G8: =('Статистика акций за год'!G8-'Статистика акций за год'!G9)/'Статистика акций за год'!G9 -> -0.056481281 | H8: =('Статистика акций за год'!H8-'Статистика акций за год'!H9)/'Статистика акций за год'!H9 -> -0.037058483 | I8: =('Статистика акций за год'!I8-'Статистика акций за год'!I9)/'Статистика акций за год'!I9 -> 0.00075075075 | ... K8: =('Статистика акций за год'!K8-'Статистика акций за год'!K9)/'Статистика акций за год'!K9 -> -0.016698926 | L8: 0.1253 | M8: =POWER(L8+1,1/365)-1 -> 0.00032347605
A9: 45261 | B9: =('Статистика акций за год'!B9-'Статистика акций за год'!B10)/'Статистика акций за год'!B10 -> 0.0060622761 | C9: =('Статистика акций за год'!C9-'Статистика акций за год'!C10)/'Статистика акций за год'!C10 -> -0.0037983214 | D9: =('Статистика акций за год'!D9-'Статистика акций за год'!D10)/'Статистика акций за год'!D10 -> -0.016899194 | E9: =('Статистика акций за год'!E9-'Статистика акций за год'!E10)/'Статистика акций за год'!E10 -> -0.015659764 | F9: =('Статистика акций за год'!F9-'Статистика акций за год'!F10)/'Статистика акций за год'!F10 -> -0.012720721 | G9: =('Статистика акций за год'!G9-'Статистика акций за год'!G10)/'Статистика акций за год'!G10 -> -0.050934483 | H9: =('Статистика акций за год'!H9-'Статистика акций за год'!H10)/'Статистика акций за год'!H10 -> -0.010315186 | I9: =('Статистика акций за год'!I9-'Статистика акций за год'!I10)/'Статистика акций за год'!I10 -> -0.015521064 | ... K9: =('Статистика акций за год'!K9-'Статистика акций за год'!K10)/'Статистика акций за год'!K10 -> -0.017694909 | L9: 0.1242 | M9: =POWER(L9+1,1/365)-1 -> 0.00032079575
A10: 45260 | B10: =('Статистика акций за год'!B10-'Статистика акций за год'!B11)/'Статистика акций за год'!B11 -> -0.01171024 | C10: =('Статистика акций за год'!C10-'Статистика акций за год'!C11)/'Статистика акций за год'!C11 -> 0.00036771465 | D10: =('Статистика акций за год'!D10-'Статистика акций за год'!D11)/'Статистика акций за год'!D11 -> -0.0079922027 | E10: =('Статистика акций за год'!E10-'Статистика акций за год'!E11)/'Статистика акций за год'!E11 -> -0.015418317 | F10: =('Статистика акций за год'!F10-'Статистика акций за год'!F11)/'Статистика акций за год'!F11 -> 0.0025289017 | G10: =('Статистика акций за год'!G10-'Статистика акций за год'!G11)/'Статистика акций за год'!G11 -> -0.00976205 | H10: =('Статистика акций за год'!H10-'Статистика акций за год'!H11)/'Статистика акций за год'!H11 -> -0.01300905 | I10: =('Статистика акций за год'!I10-'Статистика акций за год'!I11)/'Статистика акций за год'!I11 -> -0.027178602 | ... K10: =('Статистика акций за год'!K10-'Статистика акций за год'!K11)/'Статистика акций за год'!K11 -> -0.011524721 | L10: 0.115 | M10: =POWER(L10+1,1/365)-1 -> 0.00029827572
A11: 45259 | B11: =('Статистика акций за год'!B11-'Статистика акций за год'!B12)/'Статистика акций за год'!B12 -> -0.011574697 | C11: =('Статистика акций за год'!C11-'Статистика акций за год'!C12)/'Статистика акций за год'!C12 -> -0.0063333536 | D11: =('Статистика акций за год'!D11-'Статистика акций за год'!D12)/'Статистика акций за год'!D12 -> -0.018181818 | E11: =('Статистика акций за год'!E11-'Статистика акций за год'!E12)/'Статистика акций за год'!E12 -> 0.0060179691 | F11: =('Статистика акций за год'!F11-'Статистика акций за год'!F12)/'Статистика акций за год'!F12 -> -0.011110714 | G11: =('Статистика акций за год'!G11-'Статистика акций за год'!G12)/'Статистика акций за год'!G12 -> 0.01507019 | H11: =('Статистика акций за год'!H11-'Статистика акций за год'!H12)/'Статистика акций за год'!H12 -> -0.017777778 | I11: =('Статистика акций за год'!I11-'Статистика акций за год'!I12)/'Статистика акций за год'!I12 -> -0.01987315 | ... K11: =('Статистика акций за год'!K11-'Статистика акций за год'!K12)/'Статистика акций за год'!K12 -> -0.0005316274 | L11: 0.1143 | M11: =POWER(L11+1,1/365)-1 -> 0.00029655466
A12: 45258 | B12: =('Статистика акций за год'!B12-'Статистика акций за год'!B13)/'Статистика акций за год'!B13 -> -0.017715494 | C12: =('Статистика акций за год'!C12-'Статистика акций за год'!C13)/'Статистика акций за год'!C13 -> 0.0087228945 | D12: =('Статистика акций за год'!D12-'Статистика акций за год'!D13)/'Статистика акций за год'!D13 -> 0.0040353574 | E12: =('Статистика акций за год'!E12-'Статистика акций за год'!E13)/'Статистика акций за год'!E13 -> 0.020588235 | F12: =('Статистика акций за год'!F12-'Статистика акций за год'!F13)/'Статистика акций за год'!F13 -> -0.0085715298 | G12: =('Статистика акций за год'!G12-'Статистика акций за год'!G13)/'Статистика акций за год'!G13 -> 0.0089564674 | H12: =('Статистика акций за год'!H12-'Статистика акций за год'!H13)/'Статистика акций за год'!H13 -> 0.023890785 | I12: =('Статистика акций за год'!I12-'Статистика акций за год'!I13)/'Статистика акций за год'!I13 -> 0.0092460882 | ... K12: =('Статистика акций за год'!K12-'Статистика акций за год'!K13)/'Статистика акций за год'!K13 -> -0.003038735 | L12: 0.116 | M12: =POWER(L12+1,1/365)-1 -> 0.00030073251
A13: 45257 | B13: =('Статистика акций за год'!B13-'Статистика акций за год'!B14)/'Статистика акций за год'!B14 -> -0.017917424 | C13: =('Статистика акций за год'!C13-'Статистика акций за год'!C14)/'Статистика акций за год'!C14 -> -0.011656851 | D13: =('Статистика акций за год'!D13-'Статистика акций за год'!D14)/'Статистика акций за год'!D14 -> -0.010081796 | E13: =('Статистика акций за год'!E13-'Статистика акций за год'!E14)/'Статистика акций за год'!E14 -> -0.0014684288 | F13: =('Статистика акций за год'!F13-'Статистика акций за год'!F14)/'Статистика акций за год'!F14 -> -0.015757364 | G13: =('Статистика акций за год'!G13-'Статистика акций за год'!G14)/'Статистика акций за год'!G14 -> 0.025854701 | H13: =('Статистика акций за год'!H13-'Статистика акций за год'!H14)/'Статистика акций за год'!H14 -> -0.027654867 | I13: =('Статистика акций за год'!I13-'Статистика акций за год'!I14)/'Статистика акций за год'!I14 -> -0.0039671295 | ... K13: =('Статистика акций за год'!K13-'Статистика акций за год'!K14)/'Статистика акций за год'!K14 -> -0.0097100118 | L13: 0.1155 | M13: =POWER(L13+1,1/365)-1 -> 0.00029950439
A14: 45254 | B14: =('Статистика акций за год'!B14-'Статистика акций за год'!B15)/'Статистика акций за год'!B15 -> -0.0041375743 | C14: =('Статистика акций за год'!C14-'Статистика акций за год'!C15)/'Статистика акций за год'!C15 -> 0.0036560843 | D14: =('Статистика акций за год'!D14-'Статистика акций за год'!D15)/'Статистика акций за год'!D15 -> -0.012769953 | E14: =('Статистика акций за год'!E14-'Статистика акций за год'!E15)/'Статистика акций за год'!E15 -> -0.003357438 | F14: =('Статистика акций за год'!F14-'Статистика акций за год'!F15)/'Статистика акций за год'!F15 -> 0.0023061602 | G14: =('Статистика акций за год'!G14-'Статистика акций за год'!G15)/'Статистика акций за год'!G15 -> 0.0081861267 | H14: =('Статистика акций за год'!H14-'Статистика акций за год'!H15)/'Статистика акций за год'!H15 -> -0.016322089 | I14: =('Статистика акций за год'!I14-'Статистика акций за год'!I15)/'Статистика акций за год'!I15 -> 0.0041257647 | ... K14: =('Статистика акций за год'!K14-'Статистика акций за год'!K15)/'Статистика акций за год'!K15 -> -0.0050654064 | L14: 0.1154 | M14: =POWER(L14+1,1/365)-1 -> 0.0002992587
A15: 45253 | B15: =('Статистика акций за год'!B15-'Статистика акций за год'!B16)/'Статистика акций за год'!B16 -> -0.0087157139 | C15: =('Статистика акций за год'!C15-'Статистика акций за год'!C16)/'Статистика акций за год'!C16 -> -0.007619278 | D15: =('Статистика акций за год'!D15-'Статистика акций за год'!D16)/'Статистика акций за год'!D16 -> -0.013523527 | E15: =('Статистика акций за год'!E15-'Статистика акций за год'!E16)/'Статистика акций за год'!E16 -> -0.0016330039 | F15: =('Статистика акций за год'!F15-'Статистика акций за год'!F16)/'Статистика акций за год'!F16 -> 0.00010483646 | G15: =('Статистика акций за год'!G15-'Статистика акций за год'!G16)/'Статистика акций за год'!G16 -> -0.0062085207 | H15: =('Статистика акций за год'!H15-'Статистика акций за год'!H16)/'Статистика акций за год'!H16 -> -0.028027499 | I15: =('Статистика акций за год'!I15-'Статистика акций за год'!I16)/'Статистика акций за год'!I16 -> -0.0066421707 | ... K15: =('Статистика акций за год'!K15-'Статистика акций за год'!K16)/'Статистика акций за год'!K16 -> -0.0025782593 | L15: 0.1151 | M15: =POWER(L15+1,1/365)-1 -> 0.0002985215
... A256: 44908 | B256: =('Статистика акций за год'!B256-'Статистика акций за год'!B257)/'Статистика акций за год'!B257 -> -0.0064620355 | C256: =('Статистика акций за год'!C256-'Статистика акций за год'!C257)/'Статистика акций за год'!C257 -> -0.003008165 | D256: =('Статистика акций за год'!D256-'Статистика акций за год'!D257)/'Статистика акций за год'!D257 -> -0.0054089139 | E256: =('Статистика акций за год'!E256-'Статистика акций за год'!E257)/'Статистика акций за год'!E257 -> 0.0065632458 | F256: =('Статистика акций за год'!F256-'Статистика акций за год'!F257)/'Статистика акций за год'!F257 -> -0.009678807 | G256: =('Статистика акций за год'!G256-'Статистика акций за год'!G257)/'Статистика акций за год'!G257 -> -0.00053821313 | H256: =('Статистика акций за год'!H256-'Статистика акций за год'!H257)/'Статистика акций за год'!H257 -> 0.0066026411 | I256: =('Статистика акций за год'!I256-'Статистика акций за год'!I257)/'Статистика акций за год'!I257 -> -0.0026963263 | ... K256: =('Статистика акций за год'!K256-'Статистика акций за год'!K257)/'Статистика акций за год'!K257 -> 0.00010102309 | L256: 0.0702 | M256: =POWER(L256+1,1/365)-1 -> 0.00018589549
A257: 44907 | L257: 0.0711 | M257: =POWER(L257+1,1/365)-1 -> 0.00018819896
B260: Столбец 1 | C260: Столбец 2 | D260: Столбец 3 | E260: Столбец 4 | F260: Столбец 5 | G260: Столбец 6 | H260: Столбец 7 | I260: Столбец 8 | J260: Столбец 9
A261: Столбец 1 | B261: 1 | C261: =B262 -> 0.48579255 | D261: =B263 -> 0.37898025 | E261: =B264 -> 0.3900308 | F261: =B265 -> 0.45826411 | G261: =B266 -> 0.24408543 | H261: =B267 -> 0.4739845 | I261: =B268 -> 0.37738489 | J261: =B269 -> 0.48726176
A262: Столбец 2 | B262: 0.48579255 | C262: 1 | D262: =C263 -> 0.2627943 | E262: =C264 -> 0.41825955 | F262: =C265 -> 0.44623756 | G262: =C266 -> 0.20754711 | H262: =C267 -> 0.44231295 | I262: =C268 -> 0.39002893 | J262: =C269 -> 0.44317589
A263: Столбец 3 | B263: 0.37898025 | C263: 0.2627943 | D263: 1 | E263: =D264 -> 0.31300076 | F263: =D265 -> 0.32874438 | G263: =D266 -> 0.37943066 | H263: =D267 -> 0.36563232 | I263: =D268 -> 0.38073868 | J263: =D269 -> 0.36467201
A264: Столбец 4 | B264: 0.3900308 | C264: 0.41825955 | D264: 0.31300076 | E264: 1 | F264: =E265 -> 0.37893202 | G264: =E266 -> 0.29781386 | H264: =E267 -> 0.38694563 | I264: =E268 -> 0.38513806 | J264: =E269 -> 0.56203849
A265: Столбец 5 | B265: 0.45826411 | C265: 0.44623756 | D265: 0.32874438 | E265: 0.37893202 | F265: 1 | G265: =F266 -> 0.23425273 | H265: =F267 -> 0.32469762 | I265: =F268 -> 0.36882267 | J265: =F269 -> 0.40030546
A266: Столбец 6 | B266: 0.24408543 | C266: 0.20754711 | D266: 0.37943066 | E266: 0.29781386 | F266: 0.23425273 | G266: 1 | H266: =G267 -> 0.24653555 | I266: =G268 -> 0.27215529 | J266: =G269 -> 0.31639612
A267: Столбец 7 | B267: 0.4739845 | C267: 0.44231295 | D267: 0.36563232 | E267: 0.38694563 | F267: 0.32469762 | G267: 0.24653555 | H267: 1 | I267: =H268 -> 0.50087657 | J267: =H269 -> 0.44241687
A268: Столбец 8 | B268: 0.37738489 | C268: 0.39002893 | D268: 0.38073868 | E268: 0.38513806 | F268: 0.36882267 | G268: 0.27215529 | H268: 0.50087657 | I268: 1 | J268: =I269 -> 0.45575104
A269: Столбец 9 | B269: 0.48726176 | C269: 0.44317589 | D269: 0.36467201 | E269: 0.56203849 | F269: 0.40030546 | G269: 0.31639612 | H269: 0.44241687 | I269: 0.45575104 | J269: 1

Sheet Модель доходности
B1: Нахождение средней доходности и сигмы.
C3: Аэрофлот | D3: Газпром | E3: МТС | F3: Роснефть | G3: Сбербанк | H3: Башнефть | I3: М.видео | J3: ПИК | K3: Татнефть | L3: Индекс РТС | M3: Доходность облигаций на год (бескупонных с сайта ЦБ РФ)
B4: r ср. | C4: =AVERAGE(Доходность!B4:B256) -> 0.0015891122 | D4: =AVERAGE(Доходность!C4:C256) -> 3.6145201e-05 | E4: =AVERAGE(Доходность!D4:D256) -> 0.0004447362 | F4: =AVERAGE(Доходность!E4:E256) -> 0.002152081 | G4: =AVERAGE(Доходность!F4:F256) -> 0.0026584824 | H4: =AVERAGE(Доходность!G4:G256) -> 0.0036185148 | I4: =AVERAGE(Доходность!H4:H256) -> 0.00039183446 | J4: =AVERAGE(Доходность!I4:I256) -> 0.00059800717 | K4: =AVERAGE(Доходность!J4:J256) -> 0.0023519854 | L4: =AVERAGE(Доходность!K4:K250) -> 0.00042616391 | M4: =AVERAGE(Доходность!M4:M257) -> 0.00023893387
B5: σ^2 | C5: =_xlfn.VAR.S(Доходность!B4:B256) -> 0.00029842587 | D5: =_xlfn.VAR.S(Доходность!C4:C256) -> 0.00014189671 | E5: =_xlfn.VAR.S(Доходность!D4:D256) -> 0.00020970325 | F5: =_xlfn.VAR.S(Доходность!E4:E256) -> 0.00017749081 | G5: =_xlfn.VAR.S(Доходность!F4:F256) -> 0.00023716273 | H5: =_xlfn.VAR.S(Доходность!G4:G256) -> 0.00050336428 | I5: =_xlfn.VAR.S(Доходность!H4:H256) -> 0.00034909548 | J5: =_xlfn.VAR.S(Доходность!I4:I256) -> 0.00025668843 | K5: =_xlfn.VAR.S(Доходность!J4:J256) -> 0.00018249552 | L5: =_xlfn.VAR.S(Доходность!K4:K250) -> 0.00015533768 | M5: 0 | N5: (нет риска, поэтому пишем 0)
B6: σ | C6: =SQRT(C5) -> 0.017275007 | D6: =SQRT(D5) -> 0.01191204 | E6: =SQRT(E5) -> 0.014481134 | F6: =SQRT(F5) -> 0.013322568 | G6: =SQRT(G5) -> 0.015400089 | H6: =SQRT(H5) -> 0.022435781 | I6: =SQRT(I5) -> 0.018684097 | J6: =SQRT(J5) -> 0.016021499 | ... L6: =SQRT(L5) -> 0.012463454 | M6: 0

Sheet Линия эффективных портфелей
B2: Проведение ковариации через "Анализ данных". Нам понадобится для построения матрицы доли акций в портфеле. | S2: Построение линии эффективных портфелей.
C4: ='Модель доходности'!C3 -> Аэрофлот | D4: ='Модель доходности'!D3 -> Газпром | E4: ='Модель доходности'!E3 -> МТС | F4: ='Модель доходности'!F3 -> Роснефть | G4: ='Модель доходности'!G3 -> Сбербанк | H4: ='Модель доходности'!H3 -> Башнефть | I4: ='Модель доходности'!I3 -> М.видео | J4: ='Модель доходности'!J3 -> ПИК | K4: ='Модель доходности'!K3 -> Татнефть
B5: =C4 -> Аэрофлот | C5: =VARP(Доходность!$B$4:$B$256) -> 0.00029724632 | D5: =C6 -> 9.9571547e-05 | E5: =C7 -> 9.4431612e-05 | F5: =C8 -> 8.9409793e-05 | G5: =C9 -> 0.00012143316 | H5: =C10 -> 9.4228289e-05 | I5: =C11 -> 0.00015238229 | J5: =C12 -> 0.00010403654 | K5: =C13 -> 0.00011326264
B6: =D4 -> Газпром | C6: 9.9571547e-05 | D6: =VARP(Доходность!$C$4:$C$256) -> 0.00014133585 | E6: =D7 -> 4.5152802e-05 | F6: =D8 -> 6.6114997e-05 | G6: =D9 -> 8.1537147e-05 | H6: =D10 -> 5.5248954e-05 | I6: =D11 -> 9.8054594e-05 | J6: =D12 -> 7.4142316e-05 | K6: =D13 -> 7.103435e-05
B7: =E4 -> МТС | C7: 9.4431612e-05 | D7: 4.5152802e-05 | E7: =VARP(Доходность!$D$4:$D$256) -> 0.00020887438 | F7: =E8 -> 6.0147271e-05 | G7: =E9 -> 7.3023753e-05 | H7: =E10 -> 0.00012278808 | I7: =E11 -> 9.8536989e-05 | J7: =E12 -> 8.7985832e-05 | K7: =E13 -> 7.1057698e-05
B8: =F4 -> Роснефть | C8: 8.9409793e-05 | D8: 6.6114997e-05 | E8: 6.0147271e-05 | F8: =VARP(Доходность!$E$4:$E$256) -> 0.00017678927 | G8: =F9 -> 7.7437705e-05 | H8: =F10 -> 8.8665375e-05 | I8: =F11 -> 9.5937859e-05 | J8: =F12 -> 8.1881829e-05 | K8: =F13 -> 0.0001007535
B9: =G4 -> Сбербанк | C9: 0.00012143316 | D9: 8.1537147e-05 | E9: 7.3023753e-05 | F9: 7.7437705e-05 | G9: =VARP(Доходность!$F$4:$F$256) -> 0.00023622532 | H9: =G10 -> 8.0617457e-05 | I9: =G11 -> 9.305816e-05 | J9: =G12 -> 9.0640854e-05 | K9: =G13 -> 8.2950854e-05
B10: =H4 -> Башнефть | C10: 9.4228289e-05 | D10: 5.5248954e-05 | E10: 0.00012278808 | F10: 8.8665375e-05 | G10: 8.0617457e-05 | H10: =VARP(Доходность!$G$4:$G$256) -> 0.0005013747 | I10: =H11 -> 0.00010293733 | J10: =H12 -> 9.7440867e-05 | K10: =H13 -> 9.5516517e-05
B11: =I4 -> М.видео | C11: 0.00015238229 | D11: 9.8054594e-05 | E11: 9.8536989e-05 | F11: 9.5937859e-05 | G11: 9.305816e-05 | H11: 0.00010293733 | I11: =VARP(Доходность!$H$4:$H$256) -> 0.00034771566 | J11: =I12 -> 0.00014934339 | K11: =I13 -> 0.00011122692
B12: =J4 -> ПИК | C12: 0.00010403654 | D12: 7.4142316e-05 | E12: 8.7985832e-05 | F12: 8.1881829e-05 | G12: 9.0640854e-05 | H12: 9.7440867e-05 | I12: 0.00014934339 | J12: =VARP(Доходность!$I$4:$I$256) -> 0.00025567385 | K12: =J13 -> 9.825099e-05
B13: =K4 -> Татнефть | C13: 0.00011326264 | D13: 7.103435e-05 | E13: 7.1057698e-05 | F13: 0.0001007535 | G13: 8.2950854e-05 | H13: 9.5516517e-05 | I13: 0.00011122692 | J13: 9.825099e-05 | K13: =VARP(Доходность!$J$4:$J$256) -> 0.0001817742
B15: Минимальный риск портфеля находим через "Поиск решения".
B16: Строим матрицу. Доли акций в портфеле в сумме должны быть равны 1 (доли акций обозначены серой заливкой)
D18: Аэрофлот | E18: Газпром | F18: МТС | G18: Роснефть | H18: Сбербанк | I18: Башнефть | J18: М.видео | K18: ПИК | L18: Татнефть | M18: Всего | O18: Риск | P18: =SQRT(M29) -> 0.0093083674
D19: 0 | E19: 0.40807312 | F19: 0.2641564 | G19: 0.16288853 | H19: 0.049900863 | I19: 0.0052249185 | J19: 0 | K19: 0.02550317 | L19: 0.084244005 | M19: =SUM(D19:L19) -> 0.999991 | O19: Доходность | P19: =SUMPRODUCT(D19:L19,'Модель доходности'!C4:K4) -> 0.00084773786
B20: =D18 -> Аэрофлот | C20: =D19 -> 0 | D20: =D19*C$20*C5 -> 0 | E20: =E19*C$20*D5 -> 0 | F20: =F19*C$20*E5 -> 0 | G20: =$G$19*C20*F5 -> 0 | H20: =$H$19*C20*G5 -> 0 | I20: =$I$19*C20*H5 -> 0 | J20: =$J$19*$C20*I5 -> 0 | K20: =$K$19*$C20*J5 -> 0 | L20: =$L$19*$C20*K5 -> 0 | M20: =SUM(D20:L20) -> 0
B21: =E18 -> Газпром | C21: =E19 -> 0.40807312 | D21: =D19*C$21*C6 -> 0 | E21: =E19*C$21*D6 -> 2.3535765e-05 | F21: =F20*C$20*E6 -> 0 | G21: =$G$19*C21*F6 -> 4.3946922e-06 | H21: =$H$19*C21*G6 -> 1.6603573e-06 | I21: =$I$19*C21*H6 -> 1.1779899e-07 | J21: =$J$19*$C21*I6 -> 0 | K21: =$K$19*$C21*J6 -> 7.7161081e-07 | L21: =$L$19*$C21*K6 -> 2.4419986e-06 | M21: =SUM(D21:L21) -> 3.2922223e-05
B22: =F18 -> МТС | C22: =F19 -> 0.2641564 | D22: =D19*C$22*C7 -> 0 | E22: =E19*C$22*D7 -> 4.8672519e-06 | F22: =F19*C$22*E7 -> 1.4574962e-05 | G22: =$G$19*C22*F7 -> 2.5880196e-06 | H22: =$H$19*C22*G7 -> 9.6257225e-07 | I22: =$I$19*C22*H7 -> 1.6947157e-07 | J22: =$J$19*$C22*I7 -> 0 | K22: =$K$19*$C22*J7 -> 5.9274519e-07 | L22: =$L$19*$C22*K7 -> 1.5812891e-06 | M22: =SUM(D22:L22) -> 2.5336312e-05
B23: =G18 -> Роснефть | C23: =G19 -> 0.16288853 | D23: =D19*C$23*C8 -> 0 | E23: =E19*C$23*D8 -> 4.3946922e-06 | F23: =$F$19*C23*E8 -> 2.5880196e-06 | G23: =$G$19*C23*F8 -> 4.6906916e-06 | H23: =$H$19*C23*G8 -> 6.294352e-07 | I23: =$I$19*C23*H8 -> 7.5461263e-08 | J23: =$J$19*$C23*I8 -> 0 | K23: =$K$19*$C23*J8 -> 3.4015135e-07 | L23: =$L$19*$C23*K8 -> 1.3825779e-06 | M23: =SUM(D23:L23) -> 1.4101029e-05
B24: =H18 -> Сбербанк | C24: =H19 -> 0.049900863 | D24: =D19*C$24*C9 -> 0 | E24: =E19*C$24*D9 -> 1.6603573e-06 | F24: =$F$19*C24*E9 -> 9.6257225e-07 | G24: =$G$19*C24*F9 -> 6.294352e-07 | H24: =$H$19*C24*G9 -> 5.8822378e-07 | I24: =$I$19*C24*H9 -> 2.1019224e-08 | J24: =$J$19*$C24*I9 -> 0 | K24: =$K$19*$C24*J9 -> 1.1535229e-07 | L24: =$L$19*$C24*K9 -> 3.4871283e-07 | M24: =SUM(D24:L24) -> 4.3256729e-06
B25: =I18 -> Башнефть | C25: =I19 -> 0.0052249185 | D25: =D19*C$25*C10 -> 0 | E25: =E19*C$25*D10 -> 1.1779899e-07 | F25: =$F$19*C25*E10 -> 1.6947157e-07 | G25: =$G$19*C25*F10 -> 7.5461263e-08 | H25: =$H$19*C25*G10 -> 2.1019224e-08 | I25: =$I$19*C25*H10 -> 1.3687416e-08 | J25: =$J$19*$C25*I10 -> 0 | K25: =$K$19*$C25*J10 -> 1.2984189e-08 | L25: =$L$19*$C25*K10 -> 4.204332e-08 | M25: =SUM(D25:L25) -> 4.5246598e-07
B26: =J18 -> М.видео | C26: =J19 -> 0 | D26: =D19*C$26*C11 -> 0 | E26: =E19*C$26*D11 -> 0 | F26: =$F$19*C26*E11 -> 0 | G26: =$G$19*C26*F11 -> 0 | H26: =$H$19*C26*G11 -> 0 | I26: =$I$19*C26*H11 -> 0 | J26: =$J$19*$C26*I11 -> 0 | K26: =$K$19*$C26*J11 -> 0 | L26: =$L$19*$C26*K11 -> 0 | M26: =SUM(D26:L26) -> 0
B27: =K18 -> ПИК | C27: =K19 -> 0.02550317 | D27: =D19*C$27*C12 -> 0 | E27: =E19*C$27*D12 -> 7.7161081e-07 | F27: =$F$19*C27*E12 -> 5.9274519e-07 | G27: =$G$19*C27*F12 -> 3.4015135e-07 | H27: =$H$19*C27*G12 -> 1.1535229e-07 | I27: =$I$19*C27*H12 -> 1.2984189e-08 | J27: =$J$19*$C27*I12 -> 0 | K27: =$K$19*$C27*J12 -> 1.6629326e-07 | L27: =$L$19*$C27*K12 -> 2.1109119e-07 | M27: =SUM(D27:L27) -> 2.2102283e-06
B28: =L18 -> Татнефть | C28: =L19 -> 0.084244005 | D28: =D19*C$28*C13 -> 0 | E28: =E19*C$28*D13 -> 2.4419986e-06 | F28: =$F$19*C28*E13 -> 1.5812891e-06 | G28: =$G$19*C28*F13 -> 1.3825779e-06 | H28: =$H$19*C28*G13 -> 3.4871283e-07 | I28: =$I$19*C28*H13 -> 4.204332e-08 | J28: =$J$19*$C28*I13 -> 0 | K28: =$K$19*$C28*J13 -> 2.1109119e-07 | L28: =$L$19*$C28*K13 -> 1.290061e-06 | M28: =SUM(D28:L28) -> 7.2977739e-06
B29: Всего | C29: =SUM(C20:C28) -> 0.999991 | D29: =SUM(D20:D28) -> 0 | E29: =SUM(E20:E28) -> 3.7789474e-05 | F29: =SUM(F20:F28) -> 2.046906e-05 | G29: =SUM(G20:G28) -> 1.4101029e-05 | H29: =SUM(H20:H28) -> 4.3256729e-06 | I29: =SUM(I20:I28) -> 4.5246598e-07 | J29: =SUM(J20:J28) -> 0 | ... M29: =SUM(M20:M28) -> 8.6645705e-05
B31: Чтобы построить линию эффективных портфелей, нам необходимо для каждого шага найти доходность и риск. Аналогично используем "Поиск решения" для нахождения минимального риска.
B33: № | C33: 1 | D33: 2 | E33: 3 | F33: 4 | G33: 5 | H33: 6 | I33: 7 | J33: 8 | K33: 9 | L33: 10
B34: Доходность | C34: =MIN('Модель доходности'!C4:K4) -> 3.6145201e-05 | D34: =C34+(($L$34-$C$34)/9) -> 0.00043418627 | E34: =D34+(($L$34-$C$34)/9) -> 0.00083222734 | F34: =E34+(($L$34-$C$34)/9) -> 0.0012302684 | G34: =F34+(($L$34-$C$34)/9) -> 0.0016283095 | H34: =G34+(($L$34-$C$34)/9) -> 0.0020263506 | I34: =H34+(($L$34-$C$34)/9) -> 0.0024243916 | J34: =I34+(($L$34-$C$34)/9) -> 0.0028224327 | K34: =J34+(($L$34-$C$34)/9) -> 0.0032204738 | L34: =MAX('Модель доходности'!C4:K4) -> 0.0036185148
B35: Риск | C35: 0.01191204 | D35: 0.0098083692 | E35: 0.009555846 | F35: 0.0095555198 | G35: 0.0097763529 | H35: 0.010207522 | I35: 0.010831764 | J35: 0.012215944 | K35: 0.015860379 | L35: 0.022391398
D38: Аэрофлот | E38: Газпром | F38: МТС | G38: Роснефть | H38: Сбербанк | I38: Башнефть | J38: М.видео | K38: ПИК | L38: Татнефть | M38: Всего | O38: Риск | P38: =SQRT(M49) -> 0.022391398
D39: 0 | E39: 0 | F39: 0 | G39: 0 | H39: 0 | I39: 0.99999999 | J39: 0 | K39: 0 | L39: 0 | M39: =SUM(D39:L39) -> 0.99999999 | O39: Доходность | P39: =SUMPRODUCT(D39:L39,'Модель доходности'!C4:K4) -> 0.0036185148
B40: =D38 -> Аэрофлот | C40: =D39 -> 0 | D40: =$D$39*$C40*C5 -> 0 | E40: =$E$39*$C40*D5 -> 0 | F40: =$F$39*$C40*E5 -> 0 | G40: =$G$39*$C40*F5 -> 0 | H40: =$H$39*$C40*G5 -> 0 | I40: =$I$39*$C40*H5 -> 0 | J40: =$J$39*$C40*I5 -> 0 | K40: =$K$39*$C40*J5 -> 0 | L40: =$L$39*$C40*K5 -> 0 | M40: =SUM(D40:L40) -> 0
B41: =E38 -> Газпром | C41: =E39 -> 0 | D41: =$D$39*$C41*C6 -> 0 | E41: =$E$39*$C41*D6 -> 0 | F41: =$F$39*$C41*E6 -> 0 | G41: =$G$39*$C41*F6 -> 0 | H41: =$H$39*$C41*G6 -> 0 | I41: =$I$39*$C41*H6 -> 0 | J41: =$J$39*$C41*I6 -> 0 | K41: =$K$39*$C41*J6 -> 0 | L41: =$L$39*$C41*K6 -> 0 | M41: =SUM(D41:L41) -> 0
B42: =F38 -> МТС | C42: =F39 -> 0 | D42: =$D$39*$C42*C7 -> 0 | E42: =$E$39*$C42*D7 -> 0 | F42: =$F$39*$C42*E7 -> 0 | G42: =$G$39*$C42*F7 -> 0 | H42: =$H$39*$C42*G7 -> 0 | I42: =$I$39*$C42*H7 -> 0 | J42: =$J$39*$C42*I7 -> 0 | K42: =$K$39*$C42*J7 -> 0 | L42: =$L$39*$C42*K7 -> 0 | M42: =SUM(D42:L42) -> 0
B43: =G38 -> Роснефть | C43: =G39 -> 0 | D43: =$D$39*$C43*C8 -> 0 | E43: =$E$39*$C43*D8 -> 0 | F43: =$F$39*$C43*E8 -> 0 | G43: =$G$39*$C43*F8 -> 0 | H43: =$H$39*$C43*G8 -> 0 | I43: =$I$39*$C43*H8 -> 0 | J43: =$J$39*$C43*I8 -> 0 | K43: =$K$39*$C43*J8 -> 0 | L43: =$L$39*$C43*K8 -> 0 | M43: =SUM(D43:L43) -> 0
B44: =H38 -> Сбербанк | C44: =H39 -> 0 | D44: =$D$39*$C44*C9 -> 0 | E44: =$E$39*$C44*D9 -> 0 | F44: =$F$39*$C44*E9 -> 0 | G44: =$G$39*$C44*F9 -> 0 | H44: =$H$39*$C44*G9 -> 0 | I44: =$I$39*$C44*H9 -> 0 | J44: =$J$39*$C44*I9 -> 0 | K44: =$K$39*$C44*J9 -> 0 | L44: =$L$39*$C44*K9 -> 0 | M44: =SUM(D44:L44) -> 0
B45: =I38 -> Башнефть | C45: =I39 -> 0.99999999 | D45: =$D$39*$C45*C10 -> 0 | E45: =$E$39*$C45*D10 -> 0 | F45: =$F$39*$C45*E10 -> 0 | G45: =$G$39*$C45*F10 -> 0 | H45: =$H$39*$C45*G10 -> 0 | I45: =$I$39*$C45*H10 -> 0.00050137469 | J45: =$J$39*$C45*I10 -> 0 | K45: =$K$39*$C45*J10 -> 0 | L45: =$L$39*$C45*K10 -> 0 | M45: =SUM(D45:L45) -> 0.00050137469
B46: =J38 -> М.видео | C46: =J39 -> 0 | D46: =$D$39*$C46*C11 -> 0 | E46: =$E$39*$C46*D11 -> 0 | F46: =$F$39*$C46*E11 -> 0 | G46: =$G$39*$C46*F11 -> 0 | H46: =$H$39*$C46*G11 -> 0 | I46: =$I$39*$C46*H11 -> 0 | J46: =$J$39*$C46*I11 -> 0 | K46: =$K$39*$C46*J11 -> 0 | L46: =$L$39*$C46*K11 -> 0 | M46: =SUM(D46:L46) -> 0
B47: =K38 -> ПИК | C47: =K39 -> 0 | D47: =$D$39*$C47*C12 -> 0 | E47: =$E$39*$C47*D12 -> 0 | F47: =$F$39*$C47*E12 -> 0 | G47: =$G$39*$C47*F12 -> 0 | H47: =$H$39*$C47*G12 -> 0 | I47: =$I$39*$C47*H12 -> 0 | J47: =$J$39*$C47*I12 -> 0 | K47: =$K$39*$C47*J12 -> 0 | L47: =$L$39*$C47*K12 -> 0 | M47: =SUM(D47:L47) -> 0
B48: =L38 -> Татнефть | C48: =L39 -> 0 | D48: =$D$39*$C48*C13 -> 0 | E48: =$E$39*$C48*D13 -> 0 | F48: =$F$39*$C48*E13 -> 0 | G48: =$G$39*$C48*F13 -> 0 | H48: =$H$39*$C48*G13 -> 0 | I48: =$I$39*$C48*H13 -> 0 | J48: =$J$39*$C48*I13 -> 0 | K48: =$K$39*$C48*J13 -> 0 | L48: =$L$39*$C48*K13 -> 0 | M48: =SUM(D48:L48) -> 0
...

Sheet SML
B2: Расчёт бетта-коэффициентов
C4: Значение β-коэффициента | D4: r ср.
B5: ='Линия эффективных портфелей'!B5 -> Аэрофлот | C5: =_xlfn.COVARIANCE.S(Доходность!B4:B256,Доходность!K4:K256)/'Модель доходности'!$L$5 -> 0.60898632 | D5: ='Модель доходности'!C4 -> 0.0015891122
B6: ='Линия эффективных портфелей'!B6 -> Газпром | C6: =_xlfn.COVARIANCE.S(Доходность!C4:C256,Доходность!$K$4:$K$256)/'Модель доходности'!$L$5 -> 0.48315395 | D6: ='Модель доходности'!D4 -> 3.6145201e-05
B7: ='Линия эффективных портфелей'!B7 -> МТС | C7: =_xlfn.COVARIANCE.S(Доходность!D4:D256,Доходность!$K$4:$K$256)/'Модель доходности'!$L$5 -> 0.37711524 | D7: ='Модель доходности'!E4 -> 0.0004447362
B8: ='Линия эффективных портфелей'!B8 -> Роснефть | C8: =_xlfn.COVARIANCE.S(Доходность!E4:E256,Доходность!$K$4:$K$256)/'Модель доходности'!$L$5 -> 0.2827837 | D8: ='Модель доходности'!F4 -> 0.002152081
B9: ='Линия эффективных портфелей'!B9 -> Сбербанк | C9: =_xlfn.COVARIANCE.S(Доходность!F4:F256,Доходность!$K$4:$K$256)/'Модель доходности'!$L$5 -> 0.59426715 | D9: ='Модель доходности'!G4 -> 0.0026584824
B10: ='Линия эффективных портфелей'!B10 -> Башнефть | C10: =_xlfn.COVARIANCE.S(Доходность!G4:G256,Доходность!$K$4:$K$256)/'Модель доходности'!$L$5 -> 0.434988 | D10: ='Модель доходности'!H4 -> 0.0036185148
B11: ='Линия эффективных портфелей'!B11 -> М.видео | C11: =_xlfn.COVARIANCE.S(Доходность!H4:H256,Доходность!$K$4:$K$256)/'Модель доходности'!$L$5 -> 0.54989945 | D11: ='Модель доходности'!I4 -> 0.00039183446
B12: ='Линия эффективных портфелей'!B12 -> ПИК | C12: =_xlfn.COVARIANCE.S(Доходность!I4:I256,Доходность!$K$4:$K$256)/'Модель доходности'!$L$5 -> 0.37247204 | D12: ='Модель доходности'!J4 -> 0.00059800717
B13: ='Линия эффективных портфелей'!B13 -> Татнефть | C13: =_xlfn.COVARIANCE.S(Доходность!J4:J256,Доходность!$K$4:$K$256)/'Модель доходности'!$L$5 -> 0.3211129 | D13: ='Модель доходности'!K4 -> 0.0023519854
B15: Построение SML
C17: r ср. | D17: β
B18: ОФЗ (r0) | C18: ='Модель доходности'!M4 -> 0.00023893387 | D18: 0 | E18: (безрисковая доходность)
B19: Индекс РТС (rm) | C19: ='Модель доходности'!L4 -> 0.00042616391 | D19: 1
